{
  "models": [
    {
      "name": "SimpleDog",
      "description": "一只简单的体素狗，包含身体、四条腿、头部和尾巴",
      "size": {"x": 8, "y": 6, "z": 12},
      "voxels": [
        {"x": 2, "y": 0, "z": 2, "blockType": "Stone"},
        {"x": 5, "y": 0, "z": 2, "blockType": "Stone"},
        {"x": 2, "y": 0, "z": 9, "blockType": "Stone"},
        {"x": 5, "y": 0, "z": 9, "blockType": "Stone"},
        {"x": 2, "y": 1, "z": 2, "blockType": "Dirt"},
        {"x": 5, "y": 1, "z": 2, "blockType": "Dirt"},
        {"x": 2, "y": 1, "z": 9, "blockType": "Dirt"},
        {"x": 5, "y": 1, "z": 9, "blockType": "Dirt"},
        {"x": 2, "y": 2, "z": 3, "blockType": "Dirt"},
        {"x": 3, "y": 2, "z": 3, "blockType": "Dirt"},
        {"x": 4, "y": 2, "z": 3, "blockType": "Dirt"},
        {"x": 5, "y": 2, "z": 3, "blockType": "Dirt"},
        {"x": 2, "y": 2, "z": 4, "blockType": "Dirt"},
        {"x": 3, "y": 2, "z": 4, "blockType": "Dirt"},
        {"x": 4, "y": 2, "z": 4, "blockType": "Dirt"},
        {"x": 5, "y": 2, "z": 4, "blockType": "Dirt"},
        {"x": 2, "y": 2, "z": 5, "blockType": "Dirt"},
        {"x": 3, "y": 2, "z": 5, "blockType": "Dirt"},
        {"x": 4, "y": 2, "z": 5, "blockType": "Dirt"},
        {"x": 5, "y": 2, "z": 5, "blockType": "Dirt"},
        {"x": 2, "y": 2, "z": 6, "blockType": "Dirt"},
        {"x": 3, "y": 2, "z": 6, "blockType": "Dirt"},
        {"x": 4, "y": 2, "z": 6, "blockType": "Dirt"},
        {"x": 5, "y": 2, "z": 6, "blockType": "Dirt"},
        {"x": 2, "y": 2, "z": 7, "blockType": "Dirt"},
        {"x": 3, "y": 2, "z": 7, "blockType": "Dirt"},
        {"x": 4, "y": 2, "z": 7, "blockType": "Dirt"},
        {"x": 5, "y": 2, "z": 7, "blockType": "Dirt"},
        {"x": 2, "y": 2, "z": 8, "blockType": "Dirt"},
        {"x": 3, "y": 2, "z": 8, "blockType": "Dirt"},
        {"x": 4, "y": 2, "z": 8, "blockType": "Dirt"},
        {"x": 5, "y": 2, "z": 8, "blockType": "Dirt"},
        {"x": 3, "y": 3, "z": 9, "blockType": "Dirt"},
        {"x": 4, "y": 3, "z": 9, "blockType": "Dirt"},
        {"x": 3, "y": 3, "z": 10, "blockType": "Dirt"},
        {"x": 4, "y": 3, "z": 10, "blockType": "Dirt"},
        {"x": 3, "y": 4, "z": 10, "blockType": "Stone"},
        {"x": 4, "y": 4, "z": 10, "blockType": "Stone"},
        {"x": 3, "y": 3, "z": 4, "blockType": "Leaves"},
        {"x": 4, "y": 3, "z": 4, "blockType": "Leaves"},
        {"x": 3, "y": 4, "z": 4, "blockType": "Stone"},
        {"x": 4, "y": 4, "z": 4, "blockType": "Stone"}
      ]
    },
    {
      "name": "SimpleCube",
      "description": "一个简单的3x3x3立方体，用于测试",
      "size": {"x": 3, "y": 3, "z": 3},
      "voxels": [
        {"x": 0, "y": 0, "z": 0, "blockType": "Stone"},
        {"x": 1, "y": 0, "z": 0, "blockType": "Stone"},
        {"x": 2, "y": 0, "z": 0, "blockType": "Stone"},
        {"x": 0, "y": 0, "z": 1, "blockType": "Stone"},
        {"x": 1, "y": 0, "z": 1, "blockType": "Stone"},
        {"x": 2, "y": 0, "z": 1, "blockType": "Stone"},
        {"x": 0, "y": 0, "z": 2, "blockType": "Stone"},
        {"x": 1, "y": 0, "z": 2, "blockType": "Stone"},
        {"x": 2, "y": 0, "z": 2, "blockType": "Stone"},
        {"x": 0, "y": 1, "z": 0, "blockType": "Dirt"},
        {"x": 2, "y": 1, "z": 0, "blockType": "Dirt"},
        {"x": 0, "y": 1, "z": 2, "blockType": "Dirt"},
        {"x": 2, "y": 1, "z": 2, "blockType": "Dirt"},
        {"x": 0, "y": 2, "z": 0, "blockType": "Grass"},
        {"x": 1, "y": 2, "z": 0, "blockType": "Grass"},
        {"x": 2, "y": 2, "z": 0, "blockType": "Grass"},
        {"x": 0, "y": 2, "z": 1, "blockType": "Grass"},
        {"x": 1, "y": 2, "z": 1, "blockType": "Grass"},
        {"x": 2, "y": 2, "z": 1, "blockType": "Grass"},
        {"x": 0, "y": 2, "z": 2, "blockType": "Grass"},
        {"x": 1, "y": 2, "z": 2, "blockType": "Grass"},
        {"x": 2, "y": 2, "z": 2, "blockType": "Grass"}
      ]
    },
    {
      "name": "SmallPyramid",
      "description": "一个小金字塔",
      "size": {"x": 5, "y": 3, "z": 5},
      "voxels": [
        {"x": 0, "y": 0, "z": 0, "blockType": "Stone"},
        {"x": 1, "y": 0, "z": 0, "blockType": "Stone"},
        {"x": 2, "y": 0, "z": 0, "blockType": "Stone"},
        {"x": 3, "y": 0, "z": 0, "blockType": "Stone"},
        {"x": 4, "y": 0, "z": 0, "blockType": "Stone"},
        {"x": 0, "y": 0, "z": 1, "blockType": "Stone"},
        {"x": 1, "y": 0, "z": 1, "blockType": "Stone"},
        {"x": 2, "y": 0, "z": 1, "blockType": "Stone"},
        {"x": 3, "y": 0, "z": 1, "blockType": "Stone"},
        {"x": 4, "y": 0, "z": 1, "blockType": "Stone"},
        {"x": 0, "y": 0, "z": 2, "blockType": "Stone"},
        {"x": 1, "y": 0, "z": 2, "blockType": "Stone"},
        {"x": 2, "y": 0, "z": 2, "blockType": "Stone"},
        {"x": 3, "y": 0, "z": 2, "blockType": "Stone"},
        {"x": 4, "y": 0, "z": 2, "blockType": "Stone"},
        {"x": 0, "y": 0, "z": 3, "blockType": "Stone"},
        {"x": 1, "y": 0, "z": 3, "blockType": "Stone"},
        {"x": 2, "y": 0, "z": 3, "blockType": "Stone"},
        {"x": 3, "y": 0, "z": 3, "blockType": "Stone"},
        {"x": 4, "y": 0, "z": 3, "blockType": "Stone"},
        {"x": 0, "y": 0, "z": 4, "blockType": "Stone"},
        {"x": 1, "y": 0, "z": 4, "blockType": "Stone"},
        {"x": 2, "y": 0, "z": 4, "blockType": "Stone"},
        {"x": 3, "y": 0, "z": 4, "blockType": "Stone"},
        {"x": 4, "y": 0, "z": 4, "blockType": "Stone"},
        {"x": 1, "y": 1, "z": 1, "blockType": "Stone"},
        {"x": 2, "y": 1, "z": 1, "blockType": "Stone"},
        {"x": 3, "y": 1, "z": 1, "blockType": "Stone"},
        {"x": 1, "y": 1, "z": 2, "blockType": "Stone"},
        {"x": 2, "y": 1, "z": 2, "blockType": "Stone"},
        {"x": 3, "y": 1, "z": 2, "blockType": "Stone"},
        {"x": 1, "y": 1, "z": 3, "blockType": "Stone"},
        {"x": 2, "y": 1, "z": 3, "blockType": "Stone"},
        {"x": 3, "y": 1, "z": 3, "blockType": "Stone"},
        {"x": 2, "y": 2, "z": 2, "blockType": "Stone"}
      ]
    }
  ]
}
